<inh f='include/c++/4.8/stdexcept' l='112' c='std::runtime_error'/>
<def f='ceres-solver/internal/ceres/gtest/gtest.h' l='7893' ll='7896'/>
<size>16</size>
<doc f='ceres-solver/internal/ceres/gtest/gtest.h' l='7887'>// This exception is thrown by (and only by) a failed Google Test
// assertion when GTEST_FLAG(throw_on_failure) is true (if exceptions
// are enabled).  We derive it from std::runtime_error, which is for
// errors presumably detectable only at run time.  Since
// std::runtime_error inherits from std::exception, many testing
// frameworks know how to extract and print the message inside it.</doc>
<fun r='_ZN7testing8internal26GoogleTestFailureExceptionC1ERKNS_14TestPartResultE'/>
